<?xml version="1.0" encoding="UTF-8"?>
<testng-results ignored="0" total="1" passed="0" failed="1" skipped="0">
  <reporter-output>
  </reporter-output>
  <suite started-at="2019-08-26T23:15:52 PDT" name="Default suite" finished-at="2019-08-26T23:16:18 PDT" duration-ms="26298">
    <groups>
    </groups>
    <test started-at="2019-08-26T23:15:52 PDT" name="Default test" finished-at="2019-08-26T23:16:18 PDT" duration-ms="26298">
      <class name="global.coda.hospital.operations.OperationsTest">
        <test-method is-config="true" signature="SetUp()[pri:0, instance:global.coda.hospital.operations.OperationsTest@3bd40a57]" started-at="2019-08-26T23:15:52 PDT" name="SetUp" finished-at="2019-08-26T23:15:53 PDT" duration-ms="652" status="PASS">
          <reporter-output>
          </reporter-output>
        </test-method> <!-- SetUp -->
        <test-method signature="createIOTest()[pri:0, instance:global.coda.hospital.operations.OperationsTest@3bd40a57]" started-at="2019-08-26T23:15:53 PDT" name="createIOTest" finished-at="2019-08-26T23:16:18 PDT" duration-ms="25596" status="FAIL">
          <exception class="org.testng.TestException">
            <message>
              <![CDATA[
Method OperationsTest.createIOTest()[pri:0, instance:global.coda.hospital.operations.OperationsTest@3bd40a57] should have thrown an exception of type class global.coda.hospital.exceptions.HospitalExceptions]]>
            </message>
            <full-stacktrace>
              <![CDATA[org.testng.TestException: 
Method OperationsTest.createIOTest()[pri:0, instance:global.coda.hospital.operations.OperationsTest@3bd40a57] should have thrown an exception of type class global.coda.hospital.exceptions.HospitalExceptions
at org.testng.internal.ExpectedExceptionsHolder.noException(ExpectedExceptionsHolder.java:82)
at org.testng.internal.TestInvoker.considerExceptions(TestInvoker.java:729)
at org.testng.internal.TestInvoker.invokeMethod(TestInvoker.java:616)
at org.testng.internal.TestInvoker.invokeTestMethod(TestInvoker.java:172)
at org.testng.internal.MethodRunner.runInSequence(MethodRunner.java:46)
at org.testng.internal.TestInvoker$MethodInvocationAgent.invoke(TestInvoker.java:804)
at org.testng.internal.TestInvoker.invokeTestMethods(TestInvoker.java:145)
at org.testng.internal.TestMethodWorker.invokeTestMethods(TestMethodWorker.java:146)
at org.testng.internal.TestMethodWorker.run(TestMethodWorker.java:128)
at java.base/java.util.ArrayList.forEach(ArrayList.java:1540)
at org.testng.TestRunner.privateRun(TestRunner.java:770)
at org.testng.TestRunner.run(TestRunner.java:591)
at org.testng.SuiteRunner.runTest(SuiteRunner.java:402)
at org.testng.SuiteRunner.runSequentially(SuiteRunner.java:396)
at org.testng.SuiteRunner.privateRun(SuiteRunner.java:355)
at org.testng.SuiteRunner.run(SuiteRunner.java:304)
at org.testng.SuiteRunnerWorker.runSuite(SuiteRunnerWorker.java:53)
at org.testng.SuiteRunnerWorker.run(SuiteRunnerWorker.java:96)
at org.testng.TestNG.runSuitesSequentially(TestNG.java:1180)
at org.testng.TestNG.runSuitesLocally(TestNG.java:1102)
at org.testng.TestNG.runSuites(TestNG.java:1032)
at org.testng.TestNG.run(TestNG.java:1000)
at org.testng.remote.AbstractRemoteTestNG.run(AbstractRemoteTestNG.java:115)
at org.testng.remote.RemoteTestNG.initAndRun(RemoteTestNG.java:251)
at org.testng.remote.RemoteTestNG.main(RemoteTestNG.java:77)
]]>
            </full-stacktrace>
          </exception> <!-- org.testng.TestException -->
          <reporter-output>
          </reporter-output>
        </test-method> <!-- createIOTest -->
      </class> <!-- global.coda.hospital.operations.OperationsTest -->
    </test> <!-- Default test -->
  </suite> <!-- Default suite -->
</testng-results>
